<?xml version="1.0"?>
<robot name="icart_second">

<!--body-->
<property name="bd"  value="0.280"/>
<property name="bw"  value="0.320"/>
<property name="bh"  value="0.007"/>
<property name="base_mass" value="1.1"/>
<property name="base_ixx" value="${1.0/12.0*base_mass*(bw*bw+bh*bh)}"/>
<property name="base_iyy" value="${1.0/12.0*base_mass*(bh*bh+bd*bd)}"/>
<property name="base_izz" value="${1.0/12.0*base_mass*(bw*bw+bd*bd)}"/>

<!--caster-->
<property name="cr" value="0.0325"/>
<property name="caster_mass" value="0.1"/>
<property name="caster_i" value="${2.0/5.0*caster_mass*cr*cr}"/>

<!--wheel-->
<property name="wr" value="0.0325"/>
<property name="wl" value="0.01"/>
<property name="wheel_mass" value="1.0"/>
<property name="wheel_ixx" value="${1.0/12.0*wheel_mass*(3.0*wr*wr+wl*wl)}"/>
<property name="wheel_iyy" value="${1.0/12.0*wheel_mass*(3.0*wr*wr+wl*wl)}"/>
<property name="wheel_izz" value="${1.0/2.0*wheel_mass*wr*wr}"/>

<!--stick-->
<property name="sd"  value="0.030"/>
<property name="sw"  value="0.030"/>
<property name="sh"  value="0.200"/>

<property name="sr" value="0.030"/>
<property name="sl" value="0.200"/>
<property name="stick_mass" value="0.001"/>
<!--<property name="stick_ixx" value="${1.0/12.0*stick_mass*(sw*sw+sh*sh)}"/>
<property name="stick_iyy" value="${1.0/12.0*stick_mass*(sh*sh+sd*sd)}"/>
<property name="stick_izz" value="${1.0/12.0*stick_mass*(sw*sw+sd*sd)}"/>-->
<property name="stick_ixx" value="${1.0/12.0*stick_mass*(3.0*sr*sr+sl*sl)}"/>
<property name="stick_iyy" value="${1.0/12.0*stick_mass*(3.0*sr*sr+sl*sl)}"/>
<property name="stick_izz" value="${1.0/2.0*stick_mass*sr*sr}"/>

<!--table-->
<property name="tr" value="0.10"/>
<property name="tl" value="0.01"/>
<property name="table_mass" value="0.05"/>
<property name="table_ixx" value="${1.0/12.0*table_mass*(3.0*tr*tr+tl*tl)}"/>
<property name="table_iyy" value="${1.0/12.0*table_mass*(3.0*tr*tr+tl*tl)}"/>
<property name="table_izz" value="${1.0/2.0*table_mass*tr*tr}"/>

<!--stopper-->
<property name="stopper_d"  value="0.150"/>
<property name="stopper_w"  value="0.030"/>
<property name="stopper_h"  value="0.020"/>
<property name="stopper_mass" value="0.001"/>
<property name="stopper_ixx" value="${1.0/12.0*stopper_mass*(stopper_w*stopper_w+stopper_h*stopper_h)}"/>
<property name="stopper_iyy" value="${1.0/12.0*stopper_mass*(stopper_h*stopper_h+stopper_d*stopper_d)}"/>
<property name="stopper_izz" value="${1.0/12.0*stopper_mass*(stopper_w*stopper_w+stopper_d*stopper_d)}"/>


  <!--visual&collision define-->
  <!--base_foot_print-->
  <link name="base_foot_print_second">
  </link>
  <!--base_foot_print-->
  <link name="base_link_second_offset">
  </link>

  <!--icart_body-->
  <link name="base_link_second">
    <visual>
      <geometry>
        <box size="${bd} ${bw} ${bh}"/>
      </geometry>
    </visual>

    <collision>
      <geometry>
        <box size="${bd} ${bw} ${bh}"/>
      </geometry>
    </collision>

    <inertial>
      <origin xyz="0 0 0"/>
      <mass value="${base_mass}"/>
      <inertia ixx="${base_ixx}" ixy="0" ixz="0" iyy="${base_iyy}" iyz="0" izz="${base_izz}"/>
    </inertial>
  </link>

  <!--icart_caster-->
  <link name="caster_link_second">
    <visual>
      <geometry>
        <sphere radius="${cr}"/>
      </geometry>
    </visual>

    <collision>
      <geometry>
        <sphere radius="${cr}"/>
      </geometry>
    </collision>

    <inertial>
      <origin xyz="0 0 0"/>
      <mass value="${caster_mass}"/>
      <inertia ixx="${caster_i}" ixy="0" ixz="0" iyy="${caster_i}"  iyz="0" izz="${caster_i}"/>
     </inertial>

  </link>

  <!--icart_right_wheel-->
  <link name="right_wheel_link_second">
    <visual>
      <geometry>
        <cylinder radius="${wr}" length="${wl}"/>
      </geometry>
      <origin xyz="0 0 0" rpy="0 0 0"/>
      <material name="black"/>
    </visual>

    <collision>
      <geometry>
        <cylinder radius="${wr}" length="${wl}"/>
      </geometry>
    </collision>

    <inertial>
      <origin xyz="0 0 0"/>
      <mass value="${wheel_mass}"/>
      <inertia ixx="${wheel_ixx}" ixy="0" ixz="0" iyy="${wheel_iyy}" iyz="0" izz="${wheel_izz}"/>
   </inertial>
  </link>

  <!--icart_left_wheel-->
  <link name="left_wheel_link_second">
    <visual>
      <geometry>
        <cylinder radius="${wr}" length="${wl}"/>
      </geometry>
      <origin xyz="0 0 0" rpy="0 0 0"/>
      <material name="black"/>
    </visual>

    <collision>
      <geometry>
        <cylinder radius="${wr}" length="${wl}"/>
      </geometry>
    </collision>

    <inertial>
      <origin xyz="0 0 0"/>
      <mass value="${wheel_mass}"/>
      <inertia ixx="${wheel_ixx}" ixy="0" ixz="0" iyy="${wheel_iyy}" iyz="0" izz="${wheel_izz}"/>
   </inertial>
  </link>

  <!-- Hokuyo Laser -->
  <link name="hokuyo_link_second">
        <!-- laser catch itself. URG collision off-->
    <!--
    <collision>
      <origin xyz="0 0 0" rpy="0 0 0"/>
      <geometry>
        <box size="0.1 0.1 0.1"/>
      </geometry>
    </collision>
  -->

    <visual>
      <origin xyz="0 0 0" rpy="0 0 0"/>
      <geometry>
        <mesh filename="package://rrbot_description/meshes/hokuyo.dae"/>
      </geometry>
    </visual>

    <inertial>
      <mass value="1e-5" />
      <origin xyz="0 0 0" rpy="0 0 0"/>
      <inertia ixx="1e-6" ixy="0" ixz="0" iyy="1e-6" iyz="0" izz="1e-6" />
    </inertial>
  </link>

  <!--icart_stick-->
  <link name="stick_second">
    <visual>
      <geometry>
        <!--<box size="${sd} ${sw} ${sh}"/>-->
        <cylinder radius="${sr}" length="${sl}"/>
      </geometry>
    </visual>

    <collision>
      <geometry>
        <!--<box size="${sd} ${sw} ${sh}"/>-->
        <cylinder radius="${sr}" length="${sl}"/>
      </geometry>
    </collision>

    <inertial>
      <origin xyz="0 0 0"/>
      <mass value="${stick_mass}"/>
      <inertia ixx="${stick_ixx}" ixy="0" ixz="0" iyy="${stick_iyy}" iyz="0" izz="${stick_izz}"/>
    </inertial>
  </link>

  <!--icart_table-->
  <link name="table_second">
    <visual>
      <geometry>
        <cylinder radius="${tr}" length="${tl}"/>
      </geometry>
      <origin xyz="0 0 0" rpy="0 0 0"/>
      <material name="black"/>
    </visual>

    <collision>
      <geometry>
        <cylinder radius="${tr}" length="${tl}"/>
      </geometry>
    </collision>

    <inertial>
      <origin xyz="0 0 0"/>
      <mass value="${table_mass}"/>
      <inertia ixx="${table_ixx}" ixy="0" ixz="0" iyy="${table_iyy}" iyz="0" izz="${table_izz}"/>
   </inertial>
  </link>

  <!--icart_stopper-->
  <!--
  <link name="stopper1_second">
    <visual>
      <geometry>
        <box size="${stopper_d} ${stopper_w} ${stopper_h}"/>
      </geometry>
    </visual>

    <collision>
      <geometry>
        <box size="${stopper_d} ${stopper_w} ${stopper_h}"/>
      </geometry>
    </collision>

    <inertial>
      <origin xyz="0 0 0"/>
      <mass value="${stopper_mass}"/>
      <inertia ixx="${stopper_ixx}" ixy="0" ixz="0" iyy="${stopper_iyy}" iyz="0" izz="${stopper_izz}"/>
    </inertial>
  </link>

  <link name="stopper2_second">
    <visual>
      <geometry>
        <box size="${stopper_d} ${stopper_w} ${stopper_h}"/>
      </geometry>
    </visual>

    <collision>
      <geometry>
        <box size="${stopper_d} ${stopper_w} ${stopper_h}"/>
      </geometry>
    </collision>

    <inertial>
      <origin xyz="0 0 0"/>
      <mass value="${stopper_mass}"/>
      <inertia ixx="${stopper_ixx}" ixy="0" ixz="0" iyy="${stopper_iyy}" iyz="0" izz="${stopper_izz}"/>
    </inertial>
  </link>

  <link name="stopper3_second">
    <visual>
      <geometry>
        <box size="${stopper_d} ${stopper_w} ${stopper_h}"/>
      </geometry>
    </visual>

    <collision>
      <geometry>
        <box size="${stopper_d} ${stopper_w} ${stopper_h}"/>
      </geometry>
    </collision>

    <inertial>
      <origin xyz="0 0 0"/>
      <mass value="${stopper_mass}"/>
      <inertia ixx="${stopper_ixx}" ixy="0" ixz="0" iyy="${stopper_iyy}" iyz="0" izz="${stopper_izz}"/>
    </inertial>
  </link>

  <link name="stopper4_second">
    <visual>
      <geometry>
        <box size="${stopper_d} ${stopper_w} ${stopper_h}"/>
      </geometry>
    </visual>

    <collision>
      <geometry>
        <box size="${stopper_d} ${stopper_w} ${stopper_h}"/>
      </geometry>
    </collision>

    <inertial>
      <origin xyz="0 0 0"/>
      <mass value="${stopper_mass}"/>
      <inertia ixx="${stopper_ixx}" ixy="0" ixz="0" iyy="${stopper_iyy}" iyz="0" izz="${stopper_izz}"/>
    </inertial>
  </link>
  -->

  <!--joint define-->
  <!--base_link to base_foot_print-->
  <joint name="foot_print_second" type="fixed">
    <parent link="base_foot_print_second"/>
    <child link="base_link_second"/>
    <origin xyz="-0.105 0 ${cr}" rpy="0 0 0"/>
  </joint>

  <!--base_link to base_link_offset-->
  <joint name="offset_second" type="fixed">
    <parent link="base_link_second"/>
    <child link="base_link_second_offset"/>
    <origin xyz="-0.055 0 0" rpy="0 0 0"/>
  </joint>

  <!--base_link to caster-->
  <joint name="caster_joint_second" type="fixed">
    <parent link="base_link_second"/>
    <child link="caster_link_second"/>
    <origin xyz="-0.096 0 0" rpy="0 0 0"/>
  </joint>

  <!--base_link to left_wheel-->
  <joint name="left_wheel_joint_second" type="continuous">
    <parent link="base_link_second"/>
    <child link="left_wheel_link_second"/>
    <origin xyz="0.105 0.178 0" rpy="-1.5707 0 0"/>
    <axis xyz="0 0 1"/>
  </joint>

  <!--base_link to right_wheel-->
  <joint name="right_wheel_joint_second" type="continuous">
    <parent link="base_link_second"/>
    <child link="right_wheel_link_second"/>
    <origin xyz="0.105 -0.178 0" rpy="1.5707 0 0"/>
    <axis xyz="0 0 -1"/>
  </joint>

  <!--base_link to hokuyo-->
  <joint name="hokuyo_joint_second" type="fixed">
    <axis xyz="0 0 0" />
    <origin xyz="0 0 0.0825" rpy="0 0 3.141592"/>
    <parent link="base_foot_print_second"/>
    <child link="hokuyo_link_second"/>
  </joint>

  <!--base_link_offset to stick-->
  <joint name="stick_second" type="fixed">
    <parent link="base_link_second_offset"/>
    <child link="stick_second"/>
    <origin xyz="0 0 ${sh/2+bh/2}" rpy="0 0 0"/>
  </joint>

  <!--stick to table-->
  <joint name="table_joint_second" type="continuous">
    <parent link="stick_second"/>
    <child link="table_second"/>
    <origin xyz="0 0 ${tl/2}" rpy="0 0 0"/>
    <axis xyz="0 0 1" />
  </joint>

  <!--table to stopper-->
  <!--
  <joint name="stopper1_joint_second" type="fixed">
    <parent link="table_second"/>
    <child link="stopper1_second"/>
    <origin xyz="0 ${-tr/2} ${tl/2+stopper_h/2}" rpy="0 0 0"/>
  </joint>

  <joint name="stopper2_joint_second" type="fixed">
    <parent link="table_second"/>
    <child link="stopper2_second"/>
    <origin xyz="0 ${tr/2} ${tl/2+stopper_h/2}" rpy="0 0 0"/>
  </joint>

  <joint name="stopper3_joint_second" type="fixed">
    <parent link="table_second"/>
    <child link="stopper3_second"/>
    <origin xyz="${-tr/2} 0 ${tl/2+stopper_h/2}" rpy="0 0 1.57"/>
  </joint>

  <joint name="stopper4_joint_second" type="fixed">
    <parent link="table_second"/>
    <child link="stopper4_second"/>
    <origin xyz="${tr/2} 0 ${tl/2+stopper_h/2}" rpy="0 0 1.57"/>
  </joint>
  -->
  <!--define base_foot-->
  <!--
    <link name="base_footprint_second"/>
    <joint name="base_link_joint_second" type="fixed">
    <parent link="base_footprint_second"/>
    <child link="base_link_second"/>
    <origin xyz="-0.105 0 0.0545"/>
  </joint>
-->

  <!-- ===============  Transmission =============== -->

  <transmission name="left_wheel_trans">
      <type>transmission_interface/SimpleTransmission</type>
      <joint name="left_wheel_joint_second">
  <hardwareInterface>VelocityJointInterface</hardwareInterface>
      </joint>
   <actuator name="left_wheel_motor">
  <hardwareInterface>VelocityJointInterface</hardwareInterface>
  <mechanicalReduction>30</mechanicalReduction>
      </actuator>
 </transmission>

  <transmission name="right_wheel_trans">
       <type>transmission_interface/SimpleTransmission</type>
       <joint name="right_wheel_joint_second">
   <hardwareInterface>VelocityJointInterface</hardwareInterface>
       </joint>
    <actuator name="right_wheel_motor">
   <hardwareInterface>VelocityJointInterface</hardwareInterface>
   <mechanicalReduction>30</mechanicalReduction>
       </actuator>
  </transmission>



 <!-- =============== Gazebo =============== -->
  <gazebo>
    <plugin name="gazebo_ros_control" filename="libgazebo_ros_control.so">
      <robotNamespace>icart_second</robotNamespace>
      <robotParam>robot_description_second</robotParam>
    </plugin>
  </gazebo>

 <gazebo reference="base_link_second">
   <selfCollide>true</selfCollide>
    <mu1 value="0.05" />
    <mu2 value="0.05" />
  </gazebo>

 <gazebo reference="left_wheel_link_second">
   <selfCollide>true</selfCollide>
    <mu1 value="1.0" />
    <mu2 value="1.0" />
  </gazebo>

 <gazebo reference="right_wheel_link_second">
   <selfCollide>true</selfCollide>
    <mu1 value="1.0" />
    <mu2 value="1.0" />
  </gazebo>

 <gazebo reference="caster_link_second">
   <selfCollide>true</selfCollide>
     <!-- This caster is no frictional resistance. -->
    <mu1 value="0.0" />
    <mu2 value="0.0" />
  </gazebo>

  <gazebo reference="stick_second">
   <selfCollide>true</selfCollide>
     <!-- This caster is no frictional resistance. -->
    <mu1 value="1.0" />
    <mu2 value="1.0" />
  </gazebo>

  <gazebo reference="table_second">
   <selfCollide>true</selfCollide>
     <!-- This caster is no frictional resistance. -->
    <mu value="1.0" />
    <mu2 value="1.0" />
  </gazebo>

  <gazebo reference="stopper1_second">
   <selfCollide>true</selfCollide>
    <mu1 value="1.0" />
    <mu2 value="1.0" />
  </gazebo>

  <gazebo reference="stopper2_second">
   <selfCollide>true</selfCollide>
    <mu1 value="1.0" />
    <mu2 value="1.0" />
  </gazebo>

  <gazebo reference="stopper3_second">
   <selfCollide>true</selfCollide>
    <mu1 value="1.0" />
    <mu2 value="1.0" />
  </gazebo>

  <!--
  <gazebo reference="stopper4_second">
   <selfCollide>true</selfCollide>
    <mu1 value="1.0" />
    <mu2 value="1.0" />
  </gazebo>
  -->
  <!-- hokuyo -->
  <gazebo reference="hokuyo_link_second">
    <sensor type="ray" name="head_hokuyo_sensor">
      <pose>0 0 0 0 0 0</pose>
      <visualize>false</visualize>
      <update_rate>10.0</update_rate>
      <ray>
        <scan>
          <horizontal>
            <samples>720</samples>
            <resolution>1</resolution>
            <min_angle>-2.0944</min_angle>
            <max_angle>2.0944</max_angle>
          </horizontal>
        </scan>
        <range>
          <min>0.8</min>
          <max>5.6</max>
          <resolution>0.001</resolution>
        </range>
        <noise>
          <type>gaussian</type>
          <!-- Noise parameters based on published spec for Hokuyo laser
               achieving "+-30mm" accuracy at range < 10m.  A mean of 0.0m and
               stddev of 0.01m will put 99.7% of samples within 0.03m of the true
               reading. -->
          <mean>0.0</mean>
          <stddev>0.01</stddev>
        </noise>
      </ray>
      <plugin name="gazebo_ros_head_hokuyo_controller" filename="libgazebo_ros_laser.so">
        <topicName>/icart_second/laser/scan</topicName>
        <frameName>hokuyo_link_second</frameName>
      </plugin>
    </sensor>
  </gazebo>

  <!-- ground_truth_position -->
  <gazebo>
    <plugin name="p3d_base_controller" filename="libgazebo_ros_p3d.so">
     <alwaysOn>true</alwaysOn>
     <updateRate>10.0</updateRate>
     <bodyName>base_foot_print_second</bodyName>
     <topicName>/icart_second/pose_ground_truth</topicName>
     <gaussianNoise>0</gaussianNoise>
     <frameName>map</frameName>
     <xyzOffsets>0 0 0</xyzOffsets> 
     <rpyOffsets>0 0 0</rpyOffsets>
   </plugin>
 </gazebo>

</robot>
