<sdf version='1.6'>
  <world name='default'>
    <physics name='default_physics' default='0' type='ode'>
      <max_step_size>0.001</max_step_size>
      <real_time_factor>1</real_time_factor>
      <real_time_update_rate>1000</real_time_update_rate>
    </physics>
    <gui fullscreen='0'>
      <camera name='user_camera'>
        <pose frame=''>2.08918 6.12449 22.2134 2.4e-05 1.57 1.57002</pose>
        <view_controller>orbit</view_controller>
        <projection_type>perspective</projection_type>
      </camera>
    </gui>
    <model name='ground_plane'>
      <static>1</static>
      <link name='link'>
        <collision name='collision'>
          <geometry>
            <plane>
              <normal>0 0 1</normal>
              <size>100 100</size>
            </plane>
          </geometry>
          <surface>
            <friction>
              <ode>
                <mu>100</mu>
                <mu2>50</mu2>
              </ode>
              <torsional>
                <ode/>
              </torsional>
            </friction>
            <contact>
              <ode/>
            </contact>
            <bounce/>
          </surface>
          <max_contacts>10</max_contacts>
        </collision>
        <visual name='visual'>
          <cast_shadows>0</cast_shadows>
          <geometry>
            <plane>
              <normal>0 0 1</normal>
              <size>100 100</size>
            </plane>
          </geometry>
          <material>
            <script>
              <uri>file://media/materials/scripts/gazebo.material</uri>
              <name>Gazebo/Grey</name>
            </script>
          </material>
        </visual>
        <self_collide>0</self_collide>
        <kinematic>0</kinematic>
        <gravity>1</gravity>
      </link>
    </model>
    <light name='sun' type='directional'>
      <cast_shadows>1</cast_shadows>
      <pose frame=''>0 0 10 0 -0 0</pose>
      <diffuse>0.8 0.8 0.8 1</diffuse>
      <specular>0.1 0.1 0.1 1</specular>
      <attenuation>
        <range>1000</range>
        <constant>0.9</constant>
        <linear>0.01</linear>
        <quadratic>0.001</quadratic>
      </attenuation>
      <direction>-0.5 0.5 -1</direction>
    </light>
    <model name='my_mesh'>
      <pose frame=''>-3 0 0 0 -0 3.14</pose>
      <static>1</static>
      <link name='body'>
        <visual name='visual'>
          <geometry>
            <mesh>
              <uri>model://reflesh_space_no_wall.dae</uri>
              <scale>1 1 1</scale>
            </mesh>
          </geometry>
        </visual>
        <collision name='collision'>
          <geometry>
            <mesh>
              <uri>model://reflesh_space_no_wall.dae</uri>
              <scale>1 1 1</scale>
            </mesh>
          </geometry>
          <max_contacts>10</max_contacts>
          <surface>
            <contact>
              <ode/>
            </contact>
            <bounce/>
            <friction>
              <torsional>
                <ode/>
              </torsional>
              <ode/>
            </friction>
          </surface>
        </collision>
        <self_collide>0</self_collide>
        <kinematic>0</kinematic>
        <gravity>1</gravity>
      </link>
    </model>
    <gravity>0 0 -9.8</gravity>
    <magnetic_field>6e-06 2.3e-05 -4.2e-05</magnetic_field>
    <atmosphere type='adiabatic'/>
    <scene>
      <ambient>0.4 0.4 0.4 1</ambient>
      <background>0.7 0.7 0.7 1</background>
      <shadows>1</shadows>
    </scene>
    <spherical_coordinates>
      <surface_model>EARTH_WGS84</surface_model>
      <latitude_deg>0</latitude_deg>
      <longitude_deg>0</longitude_deg>
      <elevation>0</elevation>
      <heading_deg>0</heading_deg>
    </spherical_coordinates>
    <model name='icart'>
      <link name='base_foot_print'>
        <pose frame=''>0 0 0 0 -0 0</pose>
        <inertial>
          <pose frame=''>-0.113038 0 0.032587 0 -0 0</pose>
          <mass>1.20101</mass>
          <inertia>
            <ixx>0.00944869</ixx>
            <ixy>0</ixy>
            <ixz>4.80403e-06</ixz>
            <iyy>0.00809583</iyy>
            <iyz>0</iyz>
            <izz>0.0174642</izz>
          </inertia>
        </inertial>
        <collision name='base_foot_print_fixed_joint_lump__base_link_collision'>
          <pose frame=''>-0.105 0 0.0325 0 -0 0</pose>
          <geometry>
            <box>
              <size>0.28 0.32 0.007</size>
            </box>
          </geometry>
          <surface>
            <contact>
              <ode/>
            </contact>
            <friction>
              <ode>
                <mu>0.05</mu>
                <mu2>0.05</mu2>
              </ode>
              <torsional>
                <ode/>
              </torsional>
            </friction>
            <bounce/>
          </surface>
          <max_contacts>10</max_contacts>
        </collision>
        <collision name='base_foot_print_fixed_joint_lump__caster_link_collision_1'>
          <pose frame=''>-0.201 0 0.0325 0 -0 0</pose>
          <geometry>
            <sphere>
              <radius>0.0325</radius>
            </sphere>
          </geometry>
          <surface>
            <contact>
              <ode/>
            </contact>
            <friction>
              <ode>
                <mu>0</mu>
                <mu2>0</mu2>
              </ode>
              <torsional>
                <ode/>
              </torsional>
            </friction>
            <bounce/>
          </surface>
          <max_contacts>10</max_contacts>
        </collision>
        <collision name='base_foot_print_fixed_joint_lump__stick_collision_2'>
          <pose frame=''>-0.16 0 0.136 0 -0 0</pose>
          <geometry>
            <cylinder>
              <length>0.2</length>
              <radius>0.03</radius>
            </cylinder>
          </geometry>
          <surface>
            <contact>
              <ode/>
            </contact>
            <friction>
              <ode>
                <mu>1</mu>
                <mu2>1</mu2>
              </ode>
              <torsional>
                <ode/>
              </torsional>
            </friction>
            <bounce/>
          </surface>
          <max_contacts>10</max_contacts>
        </collision>
        <visual name='base_foot_print_fixed_joint_lump__base_link_visual'>
          <pose frame=''>-0.105 0 0.0325 0 -0 0</pose>
          <geometry>
            <box>
              <size>0.28 0.32 0.007</size>
            </box>
          </geometry>
          <material>
            <script>
              <uri>__default__</uri>
              <name>__default__</name>
            </script>
          </material>
        </visual>
        <visual name='base_foot_print_fixed_joint_lump__caster_link_visual_1'>
          <pose frame=''>-0.201 0 0.0325 0 -0 0</pose>
          <geometry>
            <sphere>
              <radius>0.0325</radius>
            </sphere>
          </geometry>
          <material>
            <script>
              <uri>__default__</uri>
              <name>__default__</name>
            </script>
          </material>
        </visual>
        <visual name='base_foot_print_fixed_joint_lump__stick_visual_2'>
          <pose frame=''>-0.16 0 0.136 0 -0 0</pose>
          <geometry>
            <cylinder>
              <length>0.2</length>
              <radius>0.03</radius>
            </cylinder>
          </geometry>
          <material>
            <script>
              <uri>__default__</uri>
              <name>__default__</name>
            </script>
          </material>
        </visual>
        <visual name='base_foot_print_fixed_joint_lump__hokuyo_link_visual_3'>
          <pose frame=''>0 0 0.0825 0 -0 0</pose>
          <geometry>
            <mesh>
              <scale>1 1 1</scale>
              <uri>/home/masanari/catkin_ws/src/gazebo_ros_demos/rrbot_description/meshes/hokuyo.dae</uri>
            </mesh>
          </geometry>
          <material>
            <script>
              <uri>__default__</uri>
              <name>__default__</name>
            </script>
          </material>
        </visual>
        <velocity_decay/>
        <velocity_decay/>
        <velocity_decay/>
        <gravity>1</gravity>
        <velocity_decay/>
        <self_collide>0</self_collide>
        <sensor name='head_hokuyo_sensor' type='ray'>
          <visualize>0</visualize>
          <update_rate>10</update_rate>
          <ray>
            <scan>
              <horizontal>
                <samples>720</samples>
                <resolution>1</resolution>
                <min_angle>-2.0944</min_angle>
                <max_angle>2.0944</max_angle>
              </horizontal>
              <vertical>
                <samples>1</samples>
                <min_angle>0</min_angle>
                <max_angle>0</max_angle>
              </vertical>
            </scan>
            <range>
              <min>0.4</min>
              <max>5.8</max>
              <resolution>0.001</resolution>
            </range>
            <noise>
              <type>gaussian</type>
              <mean>0</mean>
              <stddev>0.01</stddev>
            </noise>
          </ray>
          <plugin name='gazebo_ros_head_hokuyo_controller' filename='libgazebo_ros_laser.so'>
            <topicName>/icart/laser/scan</topicName>
            <frameName>hokuyo_link</frameName>
            <robotNamespace>/</robotNamespace>
          </plugin>
          <pose frame=''>0 0 0.0825 0 -0 0</pose>
        </sensor>
        <kinematic>0</kinematic>
      </link>
      <link name='left_wheel_link'>
        <pose frame=''>0 0.178 0.0325 -1.5707 0 0</pose>
        <inertial>
          <pose frame=''>0 0 0 0 -0 0</pose>
          <mass>1</mass>
          <inertia>
            <ixx>0.000272396</ixx>
            <ixy>0</ixy>
            <ixz>0</ixz>
            <iyy>0.000272396</iyy>
            <iyz>0</iyz>
            <izz>0.000528125</izz>
          </inertia>
        </inertial>
        <collision name='left_wheel_link_collision'>
          <pose frame=''>0 0 0 0 -0 0</pose>
          <geometry>
            <cylinder>
              <length>0.01</length>
              <radius>0.0325</radius>
            </cylinder>
          </geometry>
          <surface>
            <contact>
              <ode/>
            </contact>
            <friction>
              <ode>
                <mu>0.9</mu>
                <mu2>0.9</mu2>
              </ode>
              <torsional>
                <ode/>
              </torsional>
            </friction>
            <bounce/>
          </surface>
          <max_contacts>10</max_contacts>
        </collision>
        <visual name='left_wheel_link_visual'>
          <pose frame=''>0 0 0 0 -0 0</pose>
          <geometry>
            <cylinder>
              <length>0.01</length>
              <radius>0.0325</radius>
            </cylinder>
          </geometry>
          <material>
            <script>
              <uri>__default__</uri>
              <name>__default__</name>
            </script>
          </material>
        </visual>
        <gravity>1</gravity>
        <velocity_decay/>
        <self_collide>1</self_collide>
        <kinematic>0</kinematic>
      </link>
      <joint name='left_wheel_joint' type='revolute'>
        <child>left_wheel_link</child>
        <parent>base_foot_print</parent>
        <axis>
          <xyz>0 1 9.6e-05</xyz>
          <limit>
            <lower>-1e+16</lower>
            <upper>1e+16</upper>
          </limit>
          <dynamics>
            <spring_reference>0</spring_reference>
            <spring_stiffness>0</spring_stiffness>
          </dynamics>
          <use_parent_model_frame>1</use_parent_model_frame>
        </axis>
      </joint>
      <link name='table'>
        <pose frame=''>-0.16 0 0.141 0 -0 0</pose>
        <inertial>
          <pose frame=''>0 0 0 0 -0 0</pose>
          <mass>0.001</mass>
          <inertia>
            <ixx>2.50833e-06</ixx>
            <ixy>0</ixy>
            <ixz>0</ixz>
            <iyy>2.50833e-06</iyy>
            <iyz>0</iyz>
            <izz>5e-06</izz>
          </inertia>
        </inertial>
        <collision name='table_collision'>
          <pose frame=''>0 0 0 0 -0 0</pose>
          <geometry>
            <cylinder>
              <length>0.01</length>
              <radius>0.1</radius>
            </cylinder>
          </geometry>
          <surface>
            <contact>
              <ode/>
            </contact>
            <friction>
              <ode>
                <mu2>1</mu2>
              </ode>
              <torsional>
                <ode/>
              </torsional>
            </friction>
            <bounce/>
          </surface>
          <max_contacts>10</max_contacts>
        </collision>
        <visual name='table_visual'>
          <pose frame=''>0 0 0 0 -0 0</pose>
          <geometry>
            <cylinder>
              <length>0.01</length>
              <radius>0.1</radius>
            </cylinder>
          </geometry>
          <material>
            <script>
              <uri>__default__</uri>
              <name>__default__</name>
            </script>
          </material>
        </visual>
        <gravity>1</gravity>
        <velocity_decay/>
        <self_collide>1</self_collide>
        <kinematic>0</kinematic>
      </link>
      <joint name='table_joint' type='revolute'>
        <child>table</child>
        <parent>base_foot_print</parent>
        <axis>
          <xyz>0 0 1</xyz>
          <limit>
            <lower>-1e+16</lower>
            <upper>1e+16</upper>
          </limit>
          <dynamics>
            <spring_reference>0</spring_reference>
            <spring_stiffness>0</spring_stiffness>
          </dynamics>
          <use_parent_model_frame>1</use_parent_model_frame>
        </axis>
      </joint>
      <link name='right_wheel_link'>
        <pose frame=''>0 -0.178 0.0325 1.5707 -0 0</pose>
        <inertial>
          <pose frame=''>0 0 0 0 -0 0</pose>
          <mass>1</mass>
          <inertia>
            <ixx>0.000272396</ixx>
            <ixy>0</ixy>
            <ixz>0</ixz>
            <iyy>0.000272396</iyy>
            <iyz>0</iyz>
            <izz>0.000528125</izz>
          </inertia>
        </inertial>
        <collision name='right_wheel_link_collision'>
          <pose frame=''>0 0 0 0 -0 0</pose>
          <geometry>
            <cylinder>
              <length>0.01</length>
              <radius>0.0325</radius>
            </cylinder>
          </geometry>
          <surface>
            <contact>
              <ode/>
            </contact>
            <friction>
              <ode>
                <mu>0.9</mu>
                <mu2>0.9</mu2>
              </ode>
              <torsional>
                <ode/>
              </torsional>
            </friction>
            <bounce/>
          </surface>
          <max_contacts>10</max_contacts>
        </collision>
        <visual name='right_wheel_link_visual'>
          <pose frame=''>0 0 0 0 -0 0</pose>
          <geometry>
            <cylinder>
              <length>0.01</length>
              <radius>0.0325</radius>
            </cylinder>
          </geometry>
          <material>
            <script>
              <uri>__default__</uri>
              <name>__default__</name>
            </script>
          </material>
        </visual>
        <gravity>1</gravity>
        <velocity_decay/>
        <self_collide>1</self_collide>
        <kinematic>0</kinematic>
      </link>
      <joint name='right_wheel_joint' type='revolute'>
        <child>right_wheel_link</child>
        <parent>base_foot_print</parent>
        <axis>
          <xyz>0 1 -9.6e-05</xyz>
          <limit>
            <lower>-1e+16</lower>
            <upper>1e+16</upper>
          </limit>
          <dynamics>
            <spring_reference>0</spring_reference>
            <spring_stiffness>0</spring_stiffness>
          </dynamics>
          <use_parent_model_frame>1</use_parent_model_frame>
        </axis>
      </joint>
      <plugin name='gazebo_ros_control' filename='libgazebo_ros_control.so'>
        <robotNamespace>icart</robotNamespace>
        <robotParam>robot_description</robotParam>
      </plugin>
      <static>0</static>
      <plugin name='p3d_base_controller' filename='libgazebo_ros_p3d.so'>
        <alwaysOn>true</alwaysOn>
        <updateRate>10.0</updateRate>
        <bodyName>base_foot_print</bodyName>
        <topicName>/icart/pose_ground_truth</topicName>
        <gaussianNoise>0</gaussianNoise>
        <frameName>map</frameName>
        <xyzOffsets>0 0 0</xyzOffsets>
        <rpyOffsets>0 0 0</rpyOffsets>
        <robotNamespace>/</robotNamespace>
      </plugin>
      <pose frame=''>0 0 0 0 -0 0</pose>
    </model>
    <model name='unit_box_0'>
      <pose frame=''>0.987164 11.1646 0.5 0 -0 0</pose>
      <link name='link'>
        <inertial>
          <mass>1</mass>
          <inertia>
            <ixx>0.166667</ixx>
            <ixy>0</ixy>
            <ixz>0</ixz>
            <iyy>0.166667</iyy>
            <iyz>0</iyz>
            <izz>0.166667</izz>
          </inertia>
        </inertial>
        <collision name='collision'>
          <geometry>
            <box>
              <size>1 1 1</size>
            </box>
          </geometry>
          <max_contacts>10</max_contacts>
          <surface>
            <contact>
              <ode/>
            </contact>
            <bounce/>
            <friction>
              <torsional>
                <ode/>
              </torsional>
              <ode/>
            </friction>
          </surface>
        </collision>
        <visual name='visual'>
          <geometry>
            <box>
              <size>1 1 1</size>
            </box>
          </geometry>
          <material>
            <script>
              <name>Gazebo/Grey</name>
              <uri>file://media/materials/scripts/gazebo.material</uri>
            </script>
          </material>
        </visual>
        <self_collide>0</self_collide>
        <kinematic>0</kinematic>
        <gravity>1</gravity>
      </link>
    </model>
    <state world_name='default'>
      <sim_time>64 580000000</sim_time>
      <real_time>66 62094887</real_time>
      <wall_time>1568882614 954172693</wall_time>
      <iterations>64580</iterations>
      <model name='ground_plane'>
        <pose frame=''>0 0 0 0 -0 0</pose>
        <scale>1 1 1</scale>
        <link name='link'>
          <pose frame=''>0 0 0 0 -0 0</pose>
          <velocity>0 0 0 0 -0 0</velocity>
          <acceleration>0 0 0 0 -0 0</acceleration>
          <wrench>0 0 0 0 -0 0</wrench>
        </link>
      </model>
      <model name='icart'>
        <pose frame=''>-0.005496 0.000241 -2e-06 1.4e-05 1.1e-05 0.000225</pose>
        <scale>1 1 1</scale>
        <link name='base_foot_print'>
          <pose frame=''>-0.005496 0.000241 -2e-06 1.4e-05 1.1e-05 0.000225</pose>
          <velocity>-8.6e-05 0.000365 4e-06 0.028347 -1.4e-05 -0.000874</velocity>
          <acceleration>-0.003037 -0.92724 0.003612 0.144685 -0.030856 -1.75453</acceleration>
          <wrench>-0.003647 -1.11363 0.004338 0 -0 0</wrench>
        </link>
        <link name='left_wheel_link'>
          <pose frame=''>-0.005536 0.17824 0.0325 -1.57073 0.043526 0.000227</pose>
          <velocity>4.9e-05 -0.000629 0.005064 0.019654 0.001324 -0.001097</velocity>
          <acceleration>0.270335 -1.26637 10.1274 1.60865 0.673765 2.01759</acceleration>
          <wrench>0.270335 -1.26637 10.1274 0 -0 0</wrench>
        </link>
        <link name='right_wheel_link'>
          <pose frame=''>-0.005456 -0.177759 0.032495 1.57075 0.042607 0.000225</pose>
          <velocity>-0.000218 -0.000621 -0.005065 0.019633 3.5e-05 -0.001089</velocity>
          <acceleration>-0.26588 -1.25011 -10.1309 1.56788 -0.640839 2.05022</acceleration>
          <wrench>-0.26588 -1.25011 -10.1309 0 -0 0</wrench>
        </link>
        <link name='table'>
          <pose frame=''>-0.165495 0.000203 0.141 1.4e-05 1.1e-05 -1.4e-05</pose>
          <velocity>-7.8e-05 -0.003488 -1e-06 0.028349 3.3e-05 -1e-06</velocity>
          <acceleration>0.01387 -6.98327 -0.001558 0.149304 0.066994 -0.00092</acceleration>
          <wrench>1.4e-05 -0.006983 -2e-06 0 -0 0</wrench>
        </link>
      </model>
      <model name='my_mesh'>
        <pose frame=''>-3 0 0 0 -0 3.14</pose>
        <scale>1 1 1</scale>
        <link name='body'>
          <pose frame=''>-3 0 0 0 -0 3.14</pose>
          <velocity>0 0 0 0 -0 0</velocity>
          <acceleration>0 0 0 0 -0 0</acceleration>
          <wrench>0 0 0 0 -0 0</wrench>
        </link>
      </model>
      <model name='unit_box_0'>
        <pose frame=''>0.987164 11.1646 0.5 0 -0 0</pose>
        <scale>1 1 1</scale>
        <link name='link'>
          <pose frame=''>0.987164 11.1646 0.5 0 -0 0</pose>
          <velocity>0 0 0 0 -0 0</velocity>
          <acceleration>-0.004709 -9.78112 9.78158 0.712677 -0.009414 -4.3e-05</acceleration>
          <wrench>-0.004709 -9.78112 9.78158 0 -0 0</wrench>
        </link>
      </model>
      <light name='sun'>
        <pose frame=''>0 0 10 0 -0 0</pose>
      </light>
    </state>
  </world>
</sdf>
